{"nbformat":4,"nbformat_minor":0,"metadata":{"colab":{"provenance":[],"authorship_tag":"ABX9TyPOtjwDVmYtABawNwtgyeQk"},"kernelspec":{"name":"python3","display_name":"Python 3"},"language_info":{"name":"python"}},"cells":[{"cell_type":"markdown","source":["# **Assignment 10: Exception and Logging**\n","\n","### Done By: Asit Piri"],"metadata":{"id":"SIIoatx40wre"}},{"cell_type":"markdown","source":["## **Questiion 1:**\n","\n","What is the role of try and exception block?"],"metadata":{"id":"cqY0htZT1aah"}},{"cell_type":"markdown","source":["## **Solution**\n","\n","The try-except block is used in Python for exception handling. It allows you to catch and handle exceptions that may occur during the execution of a code block. The primary role of the try-except block is to prevent the program from terminating abruptly when an exception occurs and instead provide a mechanism to handle the exception gracefully.\n","\n","Here's how the try-except block works:\n","\n","1. The code that may raise an exception is placed inside the try block.\n","\n","2. If an exception occurs within the try block, the execution of the try block is halted, and the control is transferred to the except block.\n","\n","3. The except block specifies the type of exception it can handle. If the exception raised matches the specified exception type, the code within the except block is executed.\n","\n","4. If the exception raised does not match the specified exception type, the except block is skipped, and the exception is propagated to the outer try-except blocks or the program terminates if no matching except block is found.\n","\n","5. After the execution of the except block (if any), the program continues with the next statements after the try-except block.\n","\n","6. The try-except block allows us to handle exceptions in a controlled manner, providing an opportunity to handle the error condition, log the error, or take appropriate actions to recover from the error. It helps in improving the robustness and reliability of the code.\n","\n","Here's an example to illustrate the usage of try-except block:"],"metadata":{"id":"5iVwvhjbVuUO"}},{"cell_type":"markdown","source":["### **Test Cases**"],"metadata":{"id":"BviJ9i8yosct"}},{"cell_type":"code","source":["try:\n","    # Code that may raise an exception\n","    result = 10 / 0  # Division by zero error\n","    print(result)\n","except ZeroDivisionError:\n","    # Handling the specific exception (division by zero)\n","    print(\"Error: Division by zero!\")"],"metadata":{"colab":{"base_uri":"https://localhost:8080/"},"id":"HrxPoUitoWsT","executionInfo":{"status":"ok","timestamp":1687412654334,"user_tz":-330,"elapsed":5,"user":{"displayName":"Asit Piri","userId":"13533635816049476562"}},"outputId":"9ac37596-04a4-44d7-c524-c114e5d54865"},"execution_count":1,"outputs":[{"output_type":"stream","name":"stdout","text":["Error: Division by zero!\n"]}]},{"cell_type":"markdown","source":["### **Conclusion**\n","\n","In the above example, the code within the try block performs a division operation that may raise a ZeroDivisionError. If the exception occurs, it is caught by the except block, which handles the specific exception by printing an error message. Without the try-except block, the program would terminate with a ZeroDivisionError."],"metadata":{"id":"Gj5-D3dNoi1W"}},{"cell_type":"markdown","source":["## **Questiion 2:**\n","\n","What is the syntax for a basic try-except block?"],"metadata":{"id":"kTmwzwdh1aiD"}},{"cell_type":"markdown","source":["## **Solution**\n","\n","The syntax for a basic try-except block in Python with examples.\n","\n","Here's a breakdown of the syntax:\n","\n","1. The try keyword marks the start of the try block. Any code that might raise an exception is placed within this block.\n","\n","2. The code inside the try block is executed sequentially. If an exception occurs during the execution, the remaining code in the try block is skipped.\n","\n","3. The except keyword is followed by the specific exception type (or multiple exception types separated by commas) that you want to handle. It is used to define the block of code that will execute when the specified exception occurs.\n","\n","4. The code inside the except block is executed only if an exception of the specified type occurs within the try block.\n","\n","5. After the execution of the except block (if any), the program continues with the next statements after the try-except block."],"metadata":{"id":"Ekj2g16yDiOF"}},{"cell_type":"code","source":["'''\n","try:\n","  # Code that may raise an exception\n","  # ...\n","except ExceptionType:\n","  # Code to handle the exception\n","  # ...\n","\n","'''\n","\n","try:\n","    # Code that may raise an exception\n","    result = 10 / 0  # Division by zero error\n","    print(result)\n","except ZeroDivisionError:\n","    # Handling the specific exception (division by zero)\n","    print(\"Error: Division by zero!\")"],"metadata":{"colab":{"base_uri":"https://localhost:8080/"},"id":"VBbgK4lspMDz","executionInfo":{"status":"ok","timestamp":1687412954222,"user_tz":-330,"elapsed":390,"user":{"displayName":"Asit Piri","userId":"13533635816049476562"}},"outputId":"7200daf4-ab5c-4770-cc83-2a9fc8646e5b"},"execution_count":4,"outputs":[{"output_type":"stream","name":"stdout","text":["Error: Division by zero!\n"]}]},{"cell_type":"markdown","source":["### **Conclusion**\n","\n","In this example, the try block contains code that performs a division operation, which may raise a ZeroDivisionError. The except block specifies the ZeroDivisionError as the exception type to handle. If the exception occurs, the code inside the except block is executed, which prints an error message."],"metadata":{"id":"-5vte52lp6hU"}},{"cell_type":"markdown","source":["## **Questiion 3:**\n","\n","What happens if an exception occurs inside a try block and there is no matching\n","except block?"],"metadata":{"id":"zE3JHUxPBM-N"}},{"cell_type":"markdown","source":["## **Solution**\n","\n","If an exception occurs inside a try block and there is no matching except block to handle that specific exception, the exception will propagate up the call stack until it is caught by an appropriate except block or until it reaches the top-level of the program. If the exception is not caught, it will cause the program to terminate and an error message will be displayed, indicating the type of exception and the traceback.\n","\n","Here's an example to illustrate the behavior when there is no matching except block:"],"metadata":{"id":"UPFwr2nuDjgy"}},{"cell_type":"code","source":["try:\n","    # Code that may raise an exception\n","    result = 10 / 0  # Division by zero error\n","    print(result)\n","except ValueError:\n","    # This except block will not handle the ZeroDivisionError\n","    print(\"Error: Value error occurred!\")"],"metadata":{"colab":{"base_uri":"https://localhost:8080/","height":240},"id":"ne9Os3tXwkYb","executionInfo":{"status":"error","timestamp":1687414968034,"user_tz":-330,"elapsed":332,"user":{"displayName":"Asit Piri","userId":"13533635816049476562"}},"outputId":"f7985dff-6921-4c07-d63b-d2952908d391"},"execution_count":8,"outputs":[{"output_type":"error","ename":"ZeroDivisionError","evalue":"ignored","traceback":["\u001b[0;31m---------------------------------------------------------------------------\u001b[0m","\u001b[0;31mZeroDivisionError\u001b[0m                         Traceback (most recent call last)","\u001b[0;32m<ipython-input-8-03dc9aa38a81>\u001b[0m in \u001b[0;36m<cell line: 1>\u001b[0;34m()\u001b[0m\n\u001b[1;32m      1\u001b[0m \u001b[0;32mtry\u001b[0m\u001b[0;34m:\u001b[0m\u001b[0;34m\u001b[0m\u001b[0;34m\u001b[0m\u001b[0m\n\u001b[1;32m      2\u001b[0m     \u001b[0;31m# Code that may raise an exception\u001b[0m\u001b[0;34m\u001b[0m\u001b[0;34m\u001b[0m\u001b[0m\n\u001b[0;32m----> 3\u001b[0;31m     \u001b[0mresult\u001b[0m \u001b[0;34m=\u001b[0m \u001b[0;36m10\u001b[0m \u001b[0;34m/\u001b[0m \u001b[0;36m0\u001b[0m  \u001b[0;31m# Division by zero error\u001b[0m\u001b[0;34m\u001b[0m\u001b[0;34m\u001b[0m\u001b[0m\n\u001b[0m\u001b[1;32m      4\u001b[0m     \u001b[0mprint\u001b[0m\u001b[0;34m(\u001b[0m\u001b[0mresult\u001b[0m\u001b[0;34m)\u001b[0m\u001b[0;34m\u001b[0m\u001b[0;34m\u001b[0m\u001b[0m\n\u001b[1;32m      5\u001b[0m \u001b[0;32mexcept\u001b[0m \u001b[0mValueError\u001b[0m\u001b[0;34m:\u001b[0m\u001b[0;34m\u001b[0m\u001b[0;34m\u001b[0m\u001b[0m\n","\u001b[0;31mZeroDivisionError\u001b[0m: division by zero"]}]},{"cell_type":"markdown","source":["In this example, the try block contains code that performs a division operation, which raises a ZeroDivisionError. However, the except block specifies ValueError as the exception type to handle. Since there is no matching except block for ZeroDivisionError, the exception will not be caught by any except block within the try-except block. As a result, the exception will propagate up the call stack, and if not caught elsewhere, it will cause the program to terminate with a ZeroDivisionError and a traceback indicating the line where the exception occurred.\n","\n","### Correct code"],"metadata":{"id":"F9d03zYFwi1M"}},{"cell_type":"code","source":["try:\n","    # Code that may raise an exception\n","    result = 10 / 0  # Division by zero error\n","    print(result)\n","except ZeroDivisionError:\n","    # Handling the specific exception (division by zero)\n","    print(\"Error: Division by zero!\")"],"metadata":{"colab":{"base_uri":"https://localhost:8080/"},"id":"q3nvRHt0xtA5","executionInfo":{"status":"ok","timestamp":1687415112611,"user_tz":-330,"elapsed":319,"user":{"displayName":"Asit Piri","userId":"13533635816049476562"}},"outputId":"a69c375d-a9aa-44d4-f770-052584e54152"},"execution_count":9,"outputs":[{"output_type":"stream","name":"stdout","text":["Error: Division by zero!\n"]}]},{"cell_type":"markdown","source":["## **Questiion 4:**\n","\n","What is the difference between using a bare except block and specifying a specific exception type?"],"metadata":{"id":"Ht_vxIysBPJ1"}},{"cell_type":"markdown","source":["## **Solution**\n","\n","The difference between using a bare exception block and specifying a specific exception type lies in the level of control and granularity in handling exceptions.\n","\n","**Bare Exception Block:** A bare exception block, written as except:, catches all types of exceptions indiscriminately. **It is a catch-all block that will handle any exception that occurs within the corresponding try block**. This approach can be useful in certain scenarios where you want to handle any exception in a similar way or perform generic error handling. However, it can also be risky because it may catch and handle exceptions that you didn't anticipate, potentially masking underlying issues or bugs in your code. It is generally recommended to use specific exception handling whenever possible for better error handling and debugging.\n","\n","**Specific Exception Type:** Specifying a specific exception type in an except block, such as except ValueError:, **allows us to selectively catch and handle a particular type of exception**. This approach provides more control and flexibility in handling different exceptions differently based on their specific requirements. By specifying the exception type, we can handle the exception more appropriately, perform specific error handling logic, or take appropriate actions based on the type of exception that occurred. It helps in better understanding and debugging of the code by clearly identifying the expected exceptions and their handling.\n","\n","**Using a specific exception type in an except block allows for more targeted and precise exception handling, whereas a bare exception block catches all exceptions and provides a generic fallback for any type of exception.** It is generally recommended to use specific exception handling whenever possible, as it promotes better code understanding, debugging, and error handling practices."],"metadata":{"id":"0QGGcSWKDlHZ"}},{"cell_type":"markdown","source":["## **Questiion 5:**\n","\n","Can you have nested try-except blocks in Python? If yes, then give an example?"],"metadata":{"id":"2ar8o4jNBRrm"}},{"cell_type":"markdown","source":["## **Solution**\n","\n","Yes, it is possible to have nested try-except blocks in Python. This means that you can have a try block inside another try block, and each try block can have its corresponding except block(s) to handle the exceptions.\n","\n","Here's an example of nested try-except blocks:"],"metadata":{"id":"NJSabqyvDmQn"}},{"cell_type":"code","source":["try:\n","    # Outer try block\n","    try:\n","        # Inner try block\n","        x = int(input(\"Enter a number: \"))\n","        result = 10 / x\n","        print(\"Result:\", result)\n","    except ValueError:\n","        print(\"Invalid input. Please enter a valid number.\")\n","    except ZeroDivisionError:\n","        print(\"Error: Cannot divide by zero.\")\n","    else:\n","        print(\"Inner try block executed successfully.\")\n","except:\n","    print(\"An error occurred.\")\n","else:\n","    print(\"Outer try block executed successfully.\")"],"metadata":{"colab":{"base_uri":"https://localhost:8080/"},"id":"rlPUnqk7zWit","executionInfo":{"status":"ok","timestamp":1687415540471,"user_tz":-330,"elapsed":11451,"user":{"displayName":"Asit Piri","userId":"13533635816049476562"}},"outputId":"58171c36-8901-4f61-a51b-2b18c443cd65"},"execution_count":10,"outputs":[{"output_type":"stream","name":"stdout","text":["Enter a number: 10\n","Result: 1.0\n","Inner try block executed successfully.\n","Outer try block executed successfully.\n"]}]},{"cell_type":"markdown","source":["In this example, we have an outer try block that contains an inner try block. The inner try block attempts to divide 10 by a number entered by the user. It handles the specific exceptions ValueError (if the input is not a valid number) and ZeroDivisionError (if the input is zero). The inner try block also has an else block that is executed if no exceptions occur.\n","\n","The outer try block captures any other exceptions that might occur in the nested structure. If any exception occurs in either the outer or inner try blocks, the corresponding except block(s) are executed. Finally, the example also includes an else block for both the outer and inner try blocks, which are executed if no exceptions occur in their respective try blocks.\n","\n","This example demonstrates the nesting of try-except blocks, allowing for more fine-grained exception handling and control flow in complex scenarios."],"metadata":{"id":"qQuxpXptzhIB"}},{"cell_type":"markdown","source":["## **Questiion 6:**\n","\n","Can we use multiple exception blocks, if yes then give an example?"],"metadata":{"id":"-jBLSdNXBTyC"}},{"cell_type":"markdown","source":["## **Solution**\n","\n","Yes, we can use multiple except blocks to handle different types of exceptions in Python. This allows us to specify different actions or error handling logic based on the specific exception that occurs.\n","\n","Here's an example that demonstrates the use of multiple exception blocks:"],"metadata":{"id":"580WT_FqDnbm"}},{"cell_type":"code","source":["try:\n","    x = int(input(\"Enter a number: \"))\n","    result = 10 / x\n","    print(\"Result:\", result)\n","except ValueError:\n","    print(\"Invalid input. Please enter a valid number.\")\n","except ZeroDivisionError:\n","    print(\"Error: Cannot divide by zero.\")\n","except Exception as e:\n","    print(\"An error occurred:\", str(e))"],"metadata":{"colab":{"base_uri":"https://localhost:8080/"},"id":"hHcc_F5E0DaZ","executionInfo":{"status":"ok","timestamp":1687415720047,"user_tz":-330,"elapsed":10032,"user":{"displayName":"Asit Piri","userId":"13533635816049476562"}},"outputId":"22f136fc-401d-46d6-ff6a-d0afc19844f7"},"execution_count":11,"outputs":[{"output_type":"stream","name":"stdout","text":["Enter a number: 2.5\n","Invalid input. Please enter a valid number.\n"]}]},{"cell_type":"markdown","source":["In this example, we have multiple except blocks to handle different types of exceptions:\n","\n","1. The first except block ValueError handles the case where the user enters an invalid number (e.g., non-numeric input).\n","\n","2. The second except block ZeroDivisionError handles the case where the user enters zero as the input, resulting in a division by zero.\n","\n","3. The third except block Exception is a generic catch-all block that handles any other exceptions that are not explicitly caught by the previous except blocks. It captures the exception as e and prints a generic error message along with the specific exception information.\n","\n","4. By using multiple except blocks, you can tailor the exception handling based on the specific types of exceptions you anticipate and provide appropriate error messages or actions for each case."],"metadata":{"id":"sQY9sCP-0Q21"}},{"cell_type":"markdown","source":["## **Questiion 7:**\n","\n","Write the reason due to which following errors are raised:\n","\n","a. EOFError\n","\n","b. FloatingPointError\n","\n","c. IndexError\n","\n","d. MemoryError\n","\n","e. OverflowError\n","\n","f. TabError\n","\n","g. ValueError"],"metadata":{"id":"0Y6H1hCnBV-t"}},{"cell_type":"markdown","source":["## **Solution**\n","\n","**a.** **EOFError:** This error is raised when an input operation (e.g., input() function) reaches the end of the file or input stream before it can read any more data. It occurs when there is an unexpected end of input, such as reaching the end of a file while trying to read more data.\n","\n","**b.** **FloatingPointError:** This error is raised when a floating-point calculation or operation results in an exceptional condition. It typically occurs when performing arithmetic operations that involve floating-point numbers, such as division by zero or an invalid mathematical operation.\n","\n","**c.** **IndexError:** This error is raised when trying to access an index of a sequence (e.g., list, tuple, string) that is out of range or does not exist. It occurs when attempting to access an element at an invalid index position, such as accessing an element beyond the length of a list.\n","\n","**d.** **MemoryError:** This error is raised when the Python interpreter cannot allocate enough memory to perform an operation. It occurs when the system does not have enough available memory to fulfill a memory allocation request, such as creating a large list or performing a memory-intensive operation.\n","\n","**e.** **OverflowError:** This error is raised when a calculation exceeds the maximum representable value for a numeric type. It occurs when performing arithmetic operations that result in a value that is too large to be represented by the given numeric type, such as integer overflow or exceeding the limits of floating-point numbers.\n","\n","**f.** **TabError:** This error is raised when there is an issue with the indentation of code using tabs and spaces inconsistently. It occurs when the Python interpreter encounters inconsistent or incorrect indentation, such as mixing tabs and spaces or using an incorrect number of indentation levels.\n","\n","**g.** **ValueError:** This error is raised when a function or operation receives an argument of the correct type but an inappropriate value. It occurs when there is a problem with the content or format of the input data, such as passing an invalid argument to a function, providing an incorrect data type, or attempting an operation that is not allowed with the given values."],"metadata":{"id":"TfeWpRjFDovC"}},{"cell_type":"markdown","source":["## **Questiion 8:**\n","\n","Write code for the following given scenario and add try-exception block to it.\n","\n","a. Program to divide two numbers\n","\n","b. Program to convert a string to an integer\n","\n","c. Program to access an element in a list\n","\n","d. Program to handle a specific exception\n","\n","e. Program to handle any exception"],"metadata":{"id":"scVEI4SlBYAi"}},{"cell_type":"markdown","source":["## **Solution**"],"metadata":{"id":"b4ejeNfIDqN-"}},{"cell_type":"markdown","source":["**a. Program to divide two numbers**"],"metadata":{"id":"Ljsbap5V2xOX"}},{"cell_type":"code","source":["try:\n","    num1 = float(input(\"Enter the first number: \"))\n","    num2 = float(input(\"Enter the second number: \"))\n","    result = num1 / num2\n","    print(\"The result of division is:\", result)\n","except ZeroDivisionError:\n","    print(\"Error: Division by zero is not allowed.\")\n","except Exception as e:\n","    print(\"An error occurred:\", str(e))"],"metadata":{"colab":{"base_uri":"https://localhost:8080/"},"id":"uORF3_cj2zo4","executionInfo":{"status":"ok","timestamp":1687416558936,"user_tz":-330,"elapsed":8730,"user":{"displayName":"Asit Piri","userId":"13533635816049476562"}},"outputId":"803691d7-ceb5-4a57-e72b-f1b592af7e4f"},"execution_count":13,"outputs":[{"output_type":"stream","name":"stdout","text":["Enter the first number: 10\n","Enter the second number: 2.5\n","The result of division is: 4.0\n"]}]},{"cell_type":"markdown","source":["**b. Program to convert a string to an integer**"],"metadata":{"id":"Ih3A00Xg2z3K"}},{"cell_type":"code","source":["try:\n","    string_num = input(\"Enter a number as a string: \")\n","    integer_num = int(string_num)\n","    print(\"The converted integer is:\", integer_num)\n","except ValueError:\n","    print(\"Error: Invalid input. Please enter a valid integer.\")\n","except Exception as e:\n","    print(\"An error occurred:\", str(e))\n"],"metadata":{"colab":{"base_uri":"https://localhost:8080/"},"id":"HUuR2Q_j21uS","executionInfo":{"status":"ok","timestamp":1687416618539,"user_tz":-330,"elapsed":5069,"user":{"displayName":"Asit Piri","userId":"13533635816049476562"}},"outputId":"52de65f9-8175-4e8a-fef0-e9450b24b515"},"execution_count":15,"outputs":[{"output_type":"stream","name":"stdout","text":["Enter a number as a string: 2.5\n","Error: Invalid input. Please enter a valid integer.\n"]}]},{"cell_type":"markdown","source":["\n","**c. Program to access an element in a list**"],"metadata":{"id":"R27JmT8822hb"}},{"cell_type":"code","source":["try:\n","    my_list = [1, 2, 3, 4, 5]\n","    index = int(input(\"Enter the index of the element to access: \"))\n","    element = my_list[index]\n","    print(\"The element at index\", index, \"is:\", element)\n","except IndexError:\n","    print(\"Error: Index out of range. Please enter a valid index.\")\n","except Exception as e:\n","    print(\"An error occurred:\", str(e))"],"metadata":{"colab":{"base_uri":"https://localhost:8080/"},"id":"6RGR5buf24iC","executionInfo":{"status":"ok","timestamp":1687416666893,"user_tz":-330,"elapsed":8788,"user":{"displayName":"Asit Piri","userId":"13533635816049476562"}},"outputId":"dcd92ef3-4ac2-494e-f0d2-4513a6653330"},"execution_count":16,"outputs":[{"output_type":"stream","name":"stdout","text":["Enter the index of the element to access: 4\n","The element at index 4 is: 5\n"]}]},{"cell_type":"markdown","source":["\n","**d. Program to handle a specific exception**"],"metadata":{"id":"nvqakcik24zv"}},{"cell_type":"code","source":["try:\n","    num = int(input(\"Enter a number: \"))\n","    if num < 0:\n","        raise ValueError(\"Number cannot be negative\")\n","    print(\"The number is:\", num)\n","except ValueError as ve:\n","    print(\"ValueError:\", str(ve))\n","except Exception as e:\n","    print(\"An error occurred:\", str(e))"],"metadata":{"colab":{"base_uri":"https://localhost:8080/"},"id":"ov9MJAho26tY","executionInfo":{"status":"ok","timestamp":1687416706132,"user_tz":-330,"elapsed":13047,"user":{"displayName":"Asit Piri","userId":"13533635816049476562"}},"outputId":"77337e58-503d-44df-f6c5-f171f5fa5b34"},"execution_count":17,"outputs":[{"output_type":"stream","name":"stdout","text":["Enter a number: 3.6\n","ValueError: invalid literal for int() with base 10: '3.6'\n"]}]},{"cell_type":"markdown","source":["**e. Program to handle any exception**"],"metadata":{"id":"K-tewivc268t"}},{"cell_type":"code","source":["try:\n","    # Code that may raise an exception\n","    result = 10 / 0  # Division by zero to trigger an exception\n","except Exception as e:\n","    print(\"An error occurred:\", str(e))"],"metadata":{"colab":{"base_uri":"https://localhost:8080/"},"id":"oIijv3483INw","executionInfo":{"status":"ok","timestamp":1687416742220,"user_tz":-330,"elapsed":388,"user":{"displayName":"Asit Piri","userId":"13533635816049476562"}},"outputId":"91965044-87a3-4b3f-e51a-dc687f7a47d9"},"execution_count":18,"outputs":[{"output_type":"stream","name":"stdout","text":["An error occurred: division by zero\n"]}]}]}